Workbook

Sheet Pregled Izvještaja
A1: FINANCIJSKI IZVJEŠTAJ - PORTFOLIO ANALIZA
A2: Automatski generirano iz baze podataka 'podaci.csv'
A4: Ključne Metrike Analizirane Imovine
A5: Metrika / Ticker | B5: ASML | C5: BTC-USD | D5: ETH-USD | E5: GOOGL | F5: SPY | G5: TSM
A6: Početna cijena | B6: 285.90076 | C6: 7200.1743 | D6: 130.802 | E6: 67.832512 | F6: 296.12524 | G6: 53.503269
A7: Zadnja cijena | B7: 1788.4301 | C7: 63984.012 | D7: 1848.96 | E7: 346.31 | F7: 746.75 | G7: 403.45999
A8: Ukupni povrat (%) | B8: 5.2554226 | C8: 7.8864531 | D8: 13.135563 | E8: 4.1053689 | F8: 1.5217371 | G8: 6.5408475
A9: Prosječni dnevni prinos | B9: 0.0010298871 | C9: 0.0014164123 | D9: 0.0020071491 | E9: 0.00082563482 | F9: 0.00044340386 | G9: 0.001056491
A10: Dnevna volatilnost (Std Dev) | B10: 0.0228731 | C10: 0.03141607 | D10: 0.042079406 | E10: 0.016925273 | F10: 0.010586072 | G10: 0.020558368
A11: Anualizirana volatilnost | B11: 0.3630992 | C11: 0.49871465 | D11: 0.66798986 | E11: 0.26868038 | F11: 0.16804869 | G11: 0.32635398
A14: Struktura i opis Data Pipeline-a
A15: Ovaj Excel izvještaj generiran je potpuno automatski unutar vašeg Python projekta.
A16: Sustav povlači podatke s Yahoo Finance API-ja, strukturira ih i zapisuje u 'podaci.csv'.
A17: Nakon toga, ovaj modul (Izvoz_u_excel.py) pretvara te sirove podatke u vizualno privlačan
A18: i profesionalan poslovni izvještaj s ugrađenim Excel formulama.
A20: Struktura tabova:
A21: 1. Pregled Izvještaja - Ključne metrike i performanse.
A22: 2. Povijesni Podaci - Kompletna baza povijesnih cijena s dinamičkim izračunom prinosa.
A23: 3. Statistika i Korelacija - Analiza korelacija među imovinama i deskriptivna statistika.
A24: 4. Tehnički Indikatori - SMA, RSI, MACD, Bollinger Bands.
A25: 5. Vizualizacija - Ugrađeni grafikoni iz Python analize.

Sheet Povijesni Podaci
A1: Povijesne Cijene i Dnevni Prinosi
A3: Datum | B3: ASML Price | C3: ASML Return | D3: BTC-USD Price | E3: BTC-USD Return | F3: ETH-USD Price | G3: ETH-USD Return | H3: GOOGL Price | I3: GOOGL Return | J3: SPY Price | K3: SPY Return | L3: TSM Price | M3: TSM Return
A4: 2020-01-01 | B4: 285.90076 | C4: - | D4: 7200.1743 | E4: - | F4: 130.802 | G4: - | H4: 67.832512 | I4: - | J4: 296.12524 | K4: - | L4: 53.503269 | M4: -
A5: 2020-01-02 | B5: 285.90076 | C5: =(B5-B4)/B4 | D5: 6985.4702 | E5: =(D5-D4)/D4 | F5: 127.41018 | G5: =(F5-F4)/F4 | H5: 67.832512 | I5: =(H5-H4)/H4 | J5: 296.12524 | K5: =(J5-J4)/J4 | L5: 53.503269 | M5: =(L5-L4)/L4
A6: 2020-01-03 | B6: 281.29361 | C6: =(B6-B5)/B5 | D6: 7344.8843 | E6: =(D6-D5)/D5 | F6: 134.17171 | G6: =(F6-F5)/F5 | H6: 67.477661 | I6: =(H6-H5)/H5 | J6: 293.88293 | K6: =(J6-J5)/J5 | L6: 51.738834 | M6: =(L6-L5)/L5
A7: 2020-01-04 | B7: 281.29361 | C7: =(B7-B6)/B6 | D7: 7410.6567 | E7: =(D7-D6)/D6 | F7: 135.06937 | G7: =(F7-F6)/F6 | H7: 67.477661 | I7: =(H7-H6)/H6 | J7: 293.88293 | K7: =(J7-J6)/J6 | L7: 51.738834 | M7: =(L7-L6)/L6
A8: 2020-01-05 | B8: 281.29361 | C8: =(B8-B7)/B7 | D8: 7411.3174 | E8: =(D8-D7)/D7 | F8: 136.27678 | G8: =(F8-F7)/F7 | H8: 67.477661 | I8: =(H8-H7)/H7 | J8: 293.88293 | K8: =(J8-J7)/J7 | L8: 51.738834 | M8: =(L8-L7)/L7
A9: 2020-01-06 | B9: 279.05609 | C9: =(B9-B8)/B8 | D9: 7769.2192 | E9: =(D9-D8)/D8 | F9: 144.30415 | G9: =(F9-F8)/F8 | H9: 69.276207 | I9: =(H9-H8)/H8 | J9: 295.00418 | K9: =(J9-J8)/J8 | L9: 51.141792 | M9: =(L9-L8)/L8
A10: 2020-01-07 | B10: 282.08664 | C10: =(B10-B9)/B9 | D10: 8163.6924 | E10: =(D10-D9)/D9 | F10: 143.54399 | G10: =(F10-F9)/F9 | H10: 69.14241 | I10: =(H10-H9)/H9 | J10: 294.17459 | K10: =(J10-J9)/J9 | L10: 51.970543 | M10: =(L10-L9)/L9
A11: 2020-01-08 | B11: 285.0134 | C11: =(B11-B10)/B10 | D11: 8079.8628 | E11: =(D11-D10)/D10 | F11: 141.25813 | G11: =(F11-F10)/F10 | H11: 69.634537 | I11: =(H11-H10)/H10 | J11: 295.74243 | K11: =(J11-J10)/J10 | L11: 52.353722 | M11: =(L11-L10)/L10
A12: 2020-01-09 | B12: 284.53183 | C12: =(B12-B11)/B11 | D12: 7879.0713 | E12: =(D12-D11)/D11 | F12: 138.9792 | G12: =(F12-F11)/F11 | H12: 70.36554 | I12: =(H12-H11)/H11 | J12: 297.74783 | K12: =(J12-J11)/J11 | L12: 52.78146 | M12: =(L12-L11)/L11
A13: 2020-01-10 | B13: 279.62256 | C13: =(B13-B12)/B12 | D13: 8166.5542 | E13: =(D13-D12)/D12 | F13: 143.96378 | G13: =(F13-F12)/F12 | H13: 70.820023 | I13: =(H13-H12)/H12 | J13: 296.89096 | K13: =(J13-J12)/J12 | L13: 52.45174 | M13: =(L13-L12)/L12
A14: 2020-01-11 | B14: 279.62256 | C14: =(B14-B13)/B13 | D14: 8037.5376 | E14: =(D14-D13)/D13 | F14: 142.92711 | G14: =(F14-F13)/F13 | H14: 70.820023 | I14: =(H14-H13)/H13 | J14: 296.89096 | K14: =(J14-J13)/J13 | L14: 52.45174 | M14: =(L14-L13)/L13
A15: 2020-01-12 | B15: 279.62256 | C15: =(B15-B14)/B14 | D15: 8192.4941 | E15: =(D15-D14)/D14 | F15: 145.87393 | G15: =(F15-F14)/F14 | H15: 70.820023 | I15: =(H15-H14)/H14 | J15: 296.89096 | K15: =(J15-J14)/J14 | L15: 52.45174 | M15: =(L15-L14)/L14
A16: 2020-01-13 | B16: 284.59793 | C16: =(B16-B15)/B15 | D16: 8144.1943 | E16: =(D16-D15)/D15 | F16: 144.22659 | G16: =(F16-F15)/F15 | H16: 71.368675 | I16: =(H16-H15)/H15 | J16: 298.93274 | K16: =(J16-J15)/J15 | L16: 53.521091 | M16: =(L16-L15)/L15
... A2393: 2026-07-17 | B2393: 1788.4301 | C2393: =(B2393-B2392)/B2392 | D2393: 63984.012 | E2393: =(D2393-D2392)/D2392 | F2393: 1848.96 | G2393: =(F2393-F2392)/F2392 | H2393: 346.31 | I2393: =(H2393-H2392)/H2392 | J2393: 746.75 | K2393: =(J2393-J2392)/J2392 | L2393: 403.45999 | M2393: =(L2393-L2392)/L2392

Sheet Statistika i Korelacija
A1: Statistička Analiza i Matrica Korelacije
A3: Korelacija Dnevnih Prinosa
A4: Ticker | B4: ASML | C4: BTC-USD | D4: ETH-USD | E4: GOOGL | F4: SPY | G4: TSM
A5: ASML | B5: 1 | C5: 0.29340899 | D5: 0.2928342 | E5: 0.52686582 | F5: 0.69175298 | G5: 0.70441277
A6: BTC-USD | B6: 0.29340899 | C6: 1 | D6: 0.81925075 | E6: 0.27498467 | F6: 0.35765747 | G6: 0.24410732
A7: ETH-USD | B7: 0.2928342 | C7: 0.81925075 | D7: 1 | E7: 0.28803575 | F7: 0.36120139 | G7: 0.24935295
A8: GOOGL | B8: 0.52686582 | C8: 0.27498467 | D8: 0.28803575 | E8: 1 | F8: 0.71517782 | G8: 0.48163084
A9: SPY | B9: 0.69175298 | C9: 0.35765747 | D9: 0.36120139 | E9: 0.71517782 | F9: 1 | G9: 0.62470065
A10: Deskriptivna Statistika (Preko Excel Formula) | B10: 0.70441277 | C10: 0.24410732 | D10: 0.24935295 | E10: 0.48163084 | F10: 0.62470065 | G10: 1
A11: Metrika | B11: ASML | C11: BTC-USD | D11: ETH-USD | E11: GOOGL | F11: SPY | G11: TSM
A12: Broj opservacija | B12: =COUNT('Povijesni Podaci'!B4:B2393) | C12: =COUNT('Povijesni Podaci'!D4:D2393) | D12: =COUNT('Povijesni Podaci'!F4:F2393) | E12: =COUNT('Povijesni Podaci'!H4:H2393) | F12: =COUNT('Povijesni Podaci'!J4:J2393) | G12: =COUNT('Povijesni Podaci'!L4:L2393)
A13: Maksimalna cijena | B13: =MAX('Povijesni Podaci'!B4:B2393) | C13: =MAX('Povijesni Podaci'!D4:D2393) | D13: =MAX('Povijesni Podaci'!F4:F2393) | E13: =MAX('Povijesni Podaci'!H4:H2393) | F13: =MAX('Povijesni Podaci'!J4:J2393) | G13: =MAX('Povijesni Podaci'!L4:L2393)
A14: Minimalna cijena | B14: =MIN('Povijesni Podaci'!B4:B2393) | C14: =MIN('Povijesni Podaci'!D4:D2393) | D14: =MIN('Povijesni Podaci'!F4:F2393) | E14: =MIN('Povijesni Podaci'!H4:H2393) | F14: =MIN('Povijesni Podaci'!J4:J2393) | G14: =MIN('Povijesni Podaci'!L4:L2393)
A15: Prosječni dnevni prinos | B15: =AVERAGE('Povijesni Podaci'!C5:C2393) | C15: =AVERAGE('Povijesni Podaci'!E5:E2393) | D15: =AVERAGE('Povijesni Podaci'!G5:G2393) | E15: =AVERAGE('Povijesni Podaci'!I5:I2393) | F15: =AVERAGE('Povijesni Podaci'!K5:K2393) | G15: =AVERAGE('Povijesni Podaci'!M5:M2393)
A16: Dnevna volatilnost (Std Dev) | B16: =STDEV.S('Povijesni Podaci'!C5:C2393) | C16: =STDEV.S('Povijesni Podaci'!E5:E2393) | D16: =STDEV.S('Povijesni Podaci'!G5:G2393) | E16: =STDEV.S('Povijesni Podaci'!I5:I2393) | F16: =STDEV.S('Povijesni Podaci'!K5:K2393) | G16: =STDEV.S('Povijesni Podaci'!M5:M2393)

Sheet Tehnički Indikatori
A1: Tehnička Analiza i Indikatori
A2: Pregled ključnih indikatora (SMA, RSI, MACD, Bollinger Bands)
A3: Datum | B3: ASML Price | C3: ASML SMA 20 | D3: ASML RSI 14 | E3: ASML MACD | F3: ASML MACD Signal | G3: ASML BB Upper | H3: ASML BB Lower | I3: BTC-USD Price | J3: BTC-USD SMA 20 | K3: BTC-USD RSI 14 | L3: BTC-USD MACD | M3: BTC-USD MACD Signal | N3: BTC-USD BB Upper | O3: BTC-USD BB Lower | P3: ETH-USD Price | Q3: ETH-USD SMA 20 | R3: ETH-USD RSI 14 | S3: ETH-USD MACD | T3: ETH-USD MACD Signal | U3: ETH-USD BB Upper | V3: ETH-USD BB Lower | W3: GOOGL Price | X3: GOOGL SMA 20 | Y3: GOOGL RSI 14 | Z3: GOOGL MACD | AA3: GOOGL MACD Signal | AB3: GOOGL BB Upper | AC3: GOOGL BB Lower | AD3: SPY Price | AE3: SPY SMA 20 | AF3: SPY RSI 14 | AG3: SPY MACD | AH3: SPY MACD Signal | AI3: SPY BB Upper | AJ3: SPY BB Lower | AK3: TSM Price | AL3: TSM SMA 20 | AM3: TSM RSI 14 | AN3: TSM MACD | AO3: TSM MACD Signal | AP3: TSM BB Upper | AQ3: TSM BB Lower
A4: 2020-01-01 | B4: 285.90076 | C4: - | D4: - | E4: - | F4: - | G4: - | H4: - | I4: 7200.1743 | J4: - | K4: - | L4: - | M4: - | N4: - | O4: - | P4: 130.802 | Q4: - | R4: - | S4: - | T4: - | U4: - | V4: - | W4: 67.832512 | X4: - | Y4: - | Z4: - | AA4: - | AB4: - | AC4: - | AD4: 296.12524 | AE4: - | AF4: - | AG4: - | AH4: - | AI4: - | AJ4: - | AK4: 53.503269 | AL4: - | AM4: - | AN4: - | AO4: - | AP4: - | AQ4: -
A5: 2020-01-02 | B5: 285.90076 | C5: - | D5: - | E5: - | F5: - | G5: - | H5: - | I5: 6985.4702 | J5: - | K5: 0 | L5: - | M5: - | N5: - | O5: - | P5: 127.41018 | Q5: - | R5: 0 | S5: - | T5: - | U5: - | V5: - | W5: 67.832512 | X5: - | Y5: - | Z5: - | AA5: - | AB5: - | AC5: - | AD5: 296.12524 | AE5: - | AF5: - | AG5: - | AH5: - | AI5: - | AJ5: - | AK5: 53.503269 | AL5: - | AM5: - | AN5: - | AO5: - | AP5: - | AQ5: -
A6: 2020-01-03 | B6: 281.29361 | C6: - | D6: 0 | E6: - | F6: - | G6: - | H6: - | I6: 7344.8843 | J6: - | K6: 11.407915 | L6: - | M6: - | N6: - | O6: - | P6: 134.17171 | Q6: - | R6: 13.295641 | S6: - | T6: - | U6: - | V6: - | W6: 67.477661 | X6: - | Y6: 0 | Z6: - | AA6: - | AB6: - | AC6: - | AD6: 293.88293 | AE6: - | AF6: 0 | AG6: - | AH6: - | AI6: - | AJ6: - | AK6: 51.738834 | AL6: - | AM6: 0 | AN6: - | AO6: - | AP6: - | AQ6: -
A7: 2020-01-04 | B7: 281.29361 | C7: - | D7: 0 | E7: - | F7: - | G7: - | H7: - | I7: 7410.6567 | J7: - | K7: 13.355871 | L7: - | M7: - | N7: - | O7: - | P7: 135.06937 | Q7: - | R7: 14.913064 | S7: - | T7: - | U7: - | V7: - | W7: 67.477661 | X7: - | Y7: 0 | Z7: - | AA7: - | AB7: - | AC7: - | AD7: 293.88293 | AE7: - | AF7: 0 | AG7: - | AH7: - | AI7: - | AJ7: - | AK7: 51.738834 | AL7: - | AM7: 0 | AN7: - | AO7: - | AP7: - | AQ7: -
A8: 2020-01-05 | B8: 281.29361 | C8: - | D8: 0 | E8: - | F8: - | G8: - | H8: - | I8: 7411.3174 | J8: - | K8: 13.376474 | L8: - | M8: - | N8: - | O8: - | P8: 136.27678 | Q8: - | R8: 17.151758 | S8: - | T8: - | U8: - | V8: - | W8: 67.477661 | X8: - | Y8: 0 | Z8: - | AA8: - | AB8: - | AC8: - | AD8: 293.88293 | AE8: - | AF8: 0 | AG8: - | AH8: - | AI8: - | AJ8: - | AK8: 51.738834 | AL8: - | AM8: 0 | AN8: - | AO8: - | AP8: - | AQ8: -
A9: 2020-01-06 | B9: 279.05609 | C9: - | D9: 0 | E9: - | F9: - | G9: - | H9: - | I9: 7769.2192 | J9: - | K9: 23.929701 | L9: - | M9: - | N9: - | O9: - | P9: 144.30415 | Q9: - | R9: 30.284711 | S9: - | T9: - | U9: - | V9: - | W9: 69.276207 | X9: - | Y9: 86.358143 | Z9: - | AA9: - | AB9: - | AC9: - | AD9: 295.00418 | AE9: - | AF9: 38.444073 | AG9: - | AH9: - | AI9: - | AJ9: - | AK9: 51.141792 | AL9: - | AM9: 0 | AN9: - | AO9: - | AP9: - | AQ9: -
A10: 2020-01-07 | B10: 282.08664 | C10: - | D10: 35.513533 | E10: - | F10: - | G10: - | H10: - | I10: 8163.6924 | J10: - | K10: 33.540214 | L10: - | M10: - | N10: - | O10: - | P10: 143.54399 | Q10: - | R10: 29.802923 | S10: - | T10: - | U10: - | V10: - | W10: 69.14241 | X10: - | Y10: 80.770067 | Z10: - | AA10: - | AB10: - | AC10: - | AD10: 294.17459 | AE10: - | AF10: 29.429275 | AG10: - | AH10: - | AI10: - | AJ10: - | AK10: 51.970543 | AL10: - | AM10: 30.752046 | AN10: - | AO10: - | AP10: - | AQ10: -
A11: 2020-01-08 | B11: 285.0134 | C11: - | D11: 52.90742 | E11: - | F11: - | G11: - | H11: - | I11: 8079.8628 | J11: - | K11: 32.59771 | L11: - | M11: - | N11: - | O11: - | P11: 141.25813 | Q11: - | R11: 28.342759 | S11: - | T11: - | U11: - | V11: - | W11: 69.634537 | X11: - | Y11: 84.69339 | Z11: - | AA11: - | AB11: - | AC11: - | AD11: 295.74243 | AE11: - | AF11: 52.228449 | AG11: - | AH11: - | AI11: - | AJ11: - | AK11: 52.353722 | AL11: - | AM11: 39.947393 | AN11: - | AO11: - | AP11: - | AQ11: -
A12: 2020-01-09 | B12: 284.53183 | C12: - | D12: 50.494054 | E12: - | F12: - | G12: - | H12: - | I12: 7879.0713 | J12: - | K12: 30.394552 | L12: - | M12: - | N12: - | O12: - | P12: 138.9792 | Q12: - | R12: 26.926355 | S12: - | T12: - | U12: - | V12: - | W12: 70.36554 | X12: - | Y12: 88.459728 | Z12: - | AA12: - | AB12: - | AC12: - | AD12: 297.74783 | AE12: - | AF12: 66.940541 | AG12: - | AH12: - | AI12: - | AJ12: - | AK12: 52.78146 | AL12: - | AM12: 48.214124 | AN12: - | AO12: - | AP12: - | AQ12: -
A13: 2020-01-10 | B13: 279.62256 | C13: - | D13: 33.645094 | E13: - | F13: - | G13: - | H13: - | I13: 8166.5542 | J13: - | K13: 36.963585 | L13: - | M13: - | N13: - | O13: - | P13: 143.96378 | Q13: - | R13: 34.622207 | S13: - | T13: - | U13: - | V13: - | W13: 70.820023 | X13: - | Y13: 90.092055 | Z13: - | AA13: - | AB13: - | AC13: - | AD13: 296.89096 | AE13: - | AF13: 58.631756 | AG13: - | AH13: - | AI13: - | AJ13: - | AK13: 52.45174 | AL13: - | AM13: 43.26948 | AN13: - | AO13: - | AP13: - | AQ13: -
A14: 2020-01-11 | B14: 279.62256 | C14: - | D14: 33.645094 | E14: - | F14: - | G14: - | H14: - | I14: 8037.5376 | J14: - | K14: 35.351158 | L14: - | M14: - | N14: - | O14: - | P14: 142.92711 | Q14: - | R14: 33.824357 | S14: - | T14: - | U14: - | V14: - | W14: 70.820023 | X14: - | Y14: 90.092055 | Z14: - | AA14: - | AB14: - | AC14: - | AD14: 296.89096 | AE14: - | AF14: 58.631756 | AG14: - | AH14: - | AI14: - | AJ14: - | AK14: 52.45174 | AL14: - | AM14: 43.26948 | AN14: - | AO14: - | AP14: - | AQ14: -
A15: 2020-01-12 | B15: 279.62256 | C15: - | D15: 33.645094 | E15: - | F15: - | G15: - | H15: - | I15: 8192.4941 | J15: - | K15: 38.804011 | L15: - | M15: - | N15: - | O15: - | P15: 145.87393 | Q15: - | R15: 38.185089 | S15: - | T15: - | U15: - | V15: - | W15: 70.820023 | X15: - | Y15: 90.092055 | Z15: - | AA15: - | AB15: - | AC15: - | AD15: 296.89096 | AE15: - | AF15: 58.631756 | AG15: - | AH15: - | AI15: - | AJ15: - | AK15: 52.45174 | AL15: - | AM15: 43.26948 | AN15: - | AO15: - | AP15: - | AQ15: -
A16: 2020-01-13 | B16: 284.59793 | C16: - | D16: 53.34913 | E16: - | F16: - | G16: - | H16: - | I16: 8144.1943 | J16: - | K16: 38.120576 | L16: - | M16: - | N16: - | O16: - | P16: 144.22659 | Q16: - | R16: 36.728045 | S16: - | T16: - | U16: - | V16: - | W16: 71.368675 | X16: - | Y16: 91.83367 | Z16: - | AA16: - | AB16: - | AC16: - | AD16: 298.93274 | AE16: - | AF16: 69.790931 | AG16: - | AH16: - | AI16: - | AJ16: - | AK16: 53.521091 | AL16: - | AM16: 59.919738 | AN16: - | AO16: - | AP16: - | AQ16: -
A17: 2020-01-14 | B17: 285.63647 | C17: - | D17: 56.268319 | E17: - | F17: - | G17: - | H17: - | I17: 8827.7646 | J17: - | K17: 51.216014 | L17: - | M17: - | N17: - | O17: - | P17: 165.95535 | Q17: - | R17: 58.968142 | S17: - | T17: - | U17: - | V17: - | W17: 70.900803 | X17: - | Y17: 79.069509 | Z17: - | AA17: - | AB17: - | AC17: - | AD17: 298.47699 | AE17: - | AF17: 65.541014 | AG17: - | AH17: - | AI17: - | AJ17: - | AK17: 53.752781 | AL17: - | AM17: 62.488585 | AN17: - | AO17: - | AP17: - | AQ17: -
... A22: 2020-01-19 | B22: 283.26678 | C22: - | D22: 48.688632 | E22: - | F22: - | G22: - | H22: - | I22: 8706.2451 | J22: - | K22: 48.637266 | L22: - | M22: - | N22: - | O22: - | P22: 166.96985 | Q22: - | R22: 56.20431 | S22: - | T22: - | U22: - | V22: - | W22: 73.32579 | X22: - | Y22: 88.7685 | Z22: - | AA22: - | AB22: - | AC22: - | AD22: 302.5788 | AE22: - | AF22: 78.980061 | AG22: - | AH22: - | AI22: - | AJ22: - | AK22: 52.202225 | AL22: - | AM22: 43.64327 | AN22: - | AO22: - | AP22: - | AQ22: -
A23: 2020-01-20 | B23: 283.26678 | C23: 282.80464 | D23: 48.688632 | E23: - | F23: - | G23: 287.23544 | H23: 278.37384 | I23: 8657.6426 | J23: 8118.9712 | K23: 47.725025 | L23: - | M23: - | N23: 9353.6127 | O23: 6884.3298 | P23: 167.12051 | Q23: 149.281 | R23: 56.317682 | S23: - | T23: - | U23: 179.4404 | V23: 119.1216 | W23: 73.32579 | X23: 70.387382 | Y23: 88.7685 | Z23: - | AA23: - | AB23: 74.522348 | AC23: 66.252416 | AD23: 302.5788 | AE23: 297.78788 | AF23: 78.980061 | AG23: - | AH23: - | AI23: 304.09533 | AJ23: 291.48043 | AK23: 52.202225 | AL23: 52.414759 | AM23: 43.64327 | AN23: - | AO23: - | AP23: 53.794682 | AQ23: 51.034836
A24: 2020-01-21 | B24: 281.71854 | C24: 282.59553 | D24: 43.418724 | E24: - | F24: - | G24: 286.80007 | H24: 278.39099 | I24: 8745.8945 | J24: 8196.2573 | K24: 49.574468 | L24: - | M24: - | N24: 9381.2507 | O24: 7011.2638 | P24: 169.69716 | Q24: 151.22576 | R24: 58.305519 | S24: - | T24: - | U24: 181.38413 | V24: 121.06739 | W24: 73.461128 | X24: 70.668813 | Y24: 89.161334 | Z24: - | AA24: - | AB24: 74.837663 | AC24: 66.499963 | AD24: 301.98636 | AE24: 298.08094 | AF24: 73.05403 | AG24: - | AH24: - | AI24: 304.60408 | AJ24: 291.5578 | AK24: 51.89925 | AL24: 52.334558 | AM24: 40.245337 | AN24: - | AO24: - | AP24: 53.632098 | AQ24: 51.037018
A25: 2020-01-22 | B25: 279.68869 | C25: 282.28493 | D25: 37.663028 | E25: - | F25: - | G25: 286.37772 | H25: 278.19214 | I25: 8680.876 | J25: 8281.0275 | K25: 48.2209 | L25: - | M25: - | N25: 9336.851 | O25: 7225.204 | P25: 168.29416 | Q25: 153.26995 | R25: 56.790091 | S25: - | T25: - | U25: 182.14656 | V25: 124.39335 | W25: 73.541389 | X25: 70.954257 | Y25: 89.398157 | Z25: - | AA25: - | AB25: 75.087034 | AC25: 66.82148 | AD25: 302.02283 | AE25: 298.37582 | AF25: 73.187396 | AG25: - | AH25: - | AI25: 305.05798 | AJ25: 291.69366 | AK25: 51.997272 | AL25: 52.259258 | AM25: 41.82349 | AN25: - | AO25: - | AP25: 53.440838 | AQ25: 51.077679
A26: 2020-01-23 | B26: 277.86658 | C26: 282.11357 | D26: 33.384778 | E26: - | F26: - | G26: 286.64461 | H26: 277.58254 | I26: 8406.5156 | J26: 8334.1091 | K26: 42.898224 | L26: - | M26: - | N26: 9294.17 | O26: 7374.0482 | P26: 162.92856 | Q26: 154.7078 | R26: 51.298757 | S26: - | T26: - | U26: 182.42071 | V26: 126.99489 | W26: 73.582024 | X26: 71.259475 | Y26: 89.522969 | Z26: - | AA26: - | AB26: 75.208746 | AC26: 67.310203 | AD26: 302.36914 | AE26: 298.80013 | AF26: 74.479159 | AG26: - | AH26: - | AI26: 305.35762 | AJ26: 292.24264 | AK26: 51.221985 | AL26: 52.233416 | AM26: 34.142827 | AN26: - | AO26: - | AP26: 53.483541 | AQ26: 50.983291
A27: 2020-01-24 | B27: 279.29211 | C27: 282.0135 | D27: 39.203375 | E27: - | F27: - | G27: 286.70631 | H27: 277.32069 | I27: 8445.4346 | J27: 8385.848 | K27: 43.845129 | L27: - | M27: - | N27: 9242.309 | O27: 7529.387 | P27: 163.05118 | Q27: 156.10689 | R27: 51.414379 | S27: - | T27: - | U27: 182.43606 | V27: 129.77771 | W27: 72.664177 | X27: 71.518801 | Y27: 69.593093 | Z27: - | AA27: - | AB27: 75.085035 | AC27: 67.952567 | AD27: 299.68024 | AE27: 299.08999 | AF27: 53.091642 | AG27: - | AH27: - | AI27: 305.23163 | AJ27: 292.94836 | AK27: 51.444763 | AL27: 52.218712 | AM27: 37.684198 | AN27: - | AO27: - | AP27: 53.499863 | AQ27: 50.937562
A28: 2020-01-25 | B28: 279.29211 | C28: 281.91342 | D28: 39.203375 | E28: - | F28: - | G28: 286.75392 | H28: 277.07293 | I28: 8367.8477 | J28: 8433.6745 | K28: 42.337836 | L28: - | M28: - | N28: 9157.5694 | O28: 7709.7797 | P28: 161.28394 | Q28: 157.35725 | R28: 49.587165 | S28: - | T28: - | U28: 182.04529 | V28: 132.66921 | W28: 72.664177 | X28: 71.778127 | Y28: 69.593093 | Z28: - | AA28: - | AB28: 74.823285 | AC28: 68.732968 | AD28: 299.68024 | AE28: 299.37986 | AF28: 53.091642 | AG28: - | AH28: - | AI28: 305.0129 | AJ28: 293.74681 | AK28: 51.444763 | AL28: 52.204009 | AM28: 37.684198 | AN28: - | AO28: - | AP28: 53.514757 | AQ28: 50.893261
A29: 2020-01-26 | B29: 279.29211 | C29: 281.92523 | D29: 39.203375 | E29: -1.2469847 | F29: - | G29: 286.73745 | H29: 277.113 | I29: 8596.8301 | J29: 8475.0551 | K29: 48.017609 | L29: 288.04419 | M29: - | N29: 9130.395 | O29: 7819.7151 | P29: 168.0771 | Q29: 158.54589 | R29: 56.052614 | S29: 10.082101 | T29: - | U29: 182.87433 | V29: 134.21746 | W29: 72.664177 | X29: 71.947525 | Y29: 69.593093 | Z29: 1.5174305 | AA29: - | AB29: 74.775887 | AC29: 69.119163 | AD29: 299.68024 | AE29: 299.61366 | AF29: 53.091642 | AG29: 1.8937273 | AH29: - | AI29: 304.85667 | AJ29: 294.37065 | AK29: 51.444763 | AL29: 52.219157 | AM29: 37.684198 | AN29: -0.37842216 | AO29: - | AP29: 53.48443 | AQ29: 50.953884
A30: 2020-01-27 | B30: 268.38782 | C30: 281.24028 | D30: 21.370246 | E30: -2.1448266 | F30: - | G30: 288.97062 | H30: 273.50995 | I30: 8909.8193 | J30: 8512.3614 | K30: 54.60032 | L30: 299.05617 | M30: - | N30: 9177.9395 | O30: 7846.7833 | P30: 170.93089 | Q30: 159.91524 | R30: 58.462689 | S30: 9.9584721 | T30: - | U30: 183.76664 | V30: 136.06383 | W30: 70.957306 | X30: 72.03827 | Y30: 45.873162 | Z30: 1.2795776 | AA30: - | AB30: 74.590686 | AC30: 69.485854 | AD30: 294.8765 | AE30: 299.64876 | AF30: 32.358289 | AG30: 1.312788 | AH30: - | AI30: 304.74584 | AJ30: 294.55167 | AK30: 49.24369 | AL30: 52.082815 | AM30: 22.652668 | AN30: -0.55771561 | AO30: - | AP30: 53.919525 | AQ30: 50.246104
A31: 2020-01-28 | B31: 273.95798 | C31: 280.68751 | D31: 37.108331 | E31: -2.3794783 | F31: - | G31: 288.85079 | H31: 272.52424 | I31: 9358.5898 | J31: 8576.2978 | K31: 62.025688 | L31: 340.07511 | M31: - | N31: 9309.2102 | O31: 7843.3853 | P31: 176.37032 | Q31: 161.67085 | R31: 62.665354 | S31: 10.182039 | T31: - | U31: 184.90088 | V31: 138.44081 | W31: 71.887558 | X31: 72.150921 | Y31: 54.896066 | Z31: 1.1528517 | AA31: - | AB31: 74.442159 | AC31: 69.859683 | AD31: 297.96655 | AE31: 299.75996 | AF31: 46.761017 | AG31: 1.0891759 | AH31: - | AI31: 304.58815 | AJ31: 294.93177 | AK31: 50.874439 | AL31: 52.00885 | AM31: 41.326167 | AN31: -0.56174373 | AO31: - | AP31: 53.917364 | AQ31: 50.100337
A32: 2020-01-29 | B32: 279.58481 | C32: 280.44016 | D32: 48.353942 | E32: -2.0873416 | F32: - | G32: 288.41049 | H32: 272.46984 | I32: 9316.6299 | J32: 8648.1757 | K32: 61.020753 | L32: 364.98972 | M32: - | N32: 9375.1234 | O32: 7921.228 | P32: 175.05034 | Q32: 163.4744 | R32: 61.051078 | S32: 10.135866 | T32: - | U32: 184.81035 | V32: 142.13846 | W32: 72.194824 | X32: 72.242385 | Y32: 57.420879 | Z32: 1.0649383 | AA32: - | AB32: 74.374023 | AC32: 70.110747 | AD32: 297.72049 | AE32: 299.7586 | AF32: 45.922483 | AG32: 0.88193998 | AH32: - | AI32: 304.5892 | AJ32: 294.92799 | AK32: 50.963554 | AL32: 51.917955 | AM32: 42.14812 | AN32: -0.55138913 | AO32: - | AP32: 53.84461 | AQ32: 49.9913
A33: 2020-01-30 | B33: 277.92316 | C33: 280.35519 | D33: 45.752209 | E33: -1.9672256 | F33: - | G33: 288.39812 | H33: 272.31226 | I33: 9508.9932 | J33: 8715.2976 | K33: 63.907787 | L33: 395.6955 | M33: - | N33: 9500.5688 | O33: 7930.0264 | P33: 184.69048 | Q33: 165.51074 | R33: 67.612896 | S33: 10.753197 | T33: - | U33: 186.7801 | V33: 144.24138 | W33: 72.07341 | X33: 72.305054 | Y33: 56.084899 | Z33: 0.97423883 | AA33: - | AB33: 74.331736 | AC33: 70.278373 | AD33: 298.68665 | AE33: 299.84838 | AF33: 49.733985 | AG33: 0.78659734 | AH33: - | AI33: 304.51866 | AJ33: 295.1781 | AK33: 49.724884 | AL33: 51.781612 | AM33: 34.841893 | AN33: -0.63580422 | AO33: - | AP33: 53.923173 | AQ33: 49.640051
A34: 2020-01-31 | B34: 264.97018 | C34: 279.62257 | D34: 31.516411 | E34: -2.8839847 | F34: - | G34: 290.21252 | H34: 269.03262 | I34: 9350.5293 | J34: 8780.9472 | K34: 59.967506 | L34: 402.6024 | M34: - | N34: 9546.9423 | O34: 8014.9522 | P34: 180.16017 | Q34: 167.37239 | R34: 62.300966 | S34: 10.752925 | T34: - | U34: 186.75281 | V34: 147.99198 | W34: 71.009346 | X34: 72.314521 | Y34: 45.98667 | Z34: 0.80719293 | AA34: - | AB34: 74.313577 | AC34: 70.315464 | AD34: 293.26321 | AE34: 299.66699 | AF34: 34.874615 | AG34: 0.27029621 | AH34: - | AI34: 305.04853 | AJ34: 294.28545 | AK34: 48.067387 | AL34: 51.562395 | AM34: 27.877919 | AN34: -0.82691778 | AO34: - | AP34: 54.244504 | AQ34: 48.880286
A35: 2020-02-01 | B35: 264.97018 | C35: 278.88996 | D35: 31.516411 | E35: -3.5693773 | F35: - | G35: 291.34329 | H35: 266.43662 | I35: 9392.875 | J35: 8840.9663 | K35: 60.665435 | L35: 406.80372 | M35: - | N35: 9600.9092 | O35: 8081.0234 | P35: 183.67395 | Q35: 169.26239 | R35: 64.622533 | S35: 10.910472 | T35: - | U35: 187.12866 | V35: 151.39612 | W35: 71.009346 | X35: 72.323987 | Y35: 45.98667 | Z35: 0.66711774 | AA35: - | AB35: 74.29484 | AC35: 70.353134 | AD35: 293.26321 | AE35: 299.4856 | AF35: 34.874615 | AG35: -0.13729352 | AH35: - | AI35: 305.4717 | AJ35: 293.49951 | AK35: 48.067387 | AL35: 51.343177 | AM35: 27.877919 | AN35: -0.96722707 | AO35: - | AP35: 54.40854 | AQ35: 48.277814
A36: 2020-02-02 | B36: 264.97018 | C36: 277.90857 | D36: 31.516411 | E36: -4.0656891 | F36: - | G36: 291.50867 | H36: 264.30847 | I36: 9344.3652 | J36: 8900.9748 | K36: 59.388106 | L36: 401.5897 | M36: - | N36: 9617.5583 | O36: 8184.3913 | P36: 188.61754 | Q36: 171.48194 | R36: 67.641714 | S36: 11.303932 | T36: - | U36: 187.14631 | V36: 155.81757 | W36: 71.009346 | X36: 72.30602 | Y36: 45.98667 | Z36: 0.54976974 | AA36: - | AB36: 74.319629 | AC36: 70.292412 | AD36: 293.26321 | AE36: 299.20213 | AF36: 34.874615 | AG36: -0.4550656 | AH36: - | AI36: 305.80379 | AJ36: 292.60047 | AK36: 48.067387 | AL36: 51.070492 | AM36: 27.877919 | AN36: -1.0661335 | AO36: - | AP36: 54.286684 | AQ36: 47.8543
A37: 2020-02-03 | B37: 272.0509 | C37: 277.22929 | D37: 43.51579 | E37: -3.8433611 | F37: -2.6875854 | G37: 290.55861 | H37: 263.89997 | I37: 9293.5215 | J37: 8924.2626 | K37: 58.009457 | L37: 388.8722 | M37: 365.30319 | N37: 9660.8227 | O37: 8187.7026 | P37: 189.86507 | Q37: 172.67743 | R37: 68.375185 | S37: 11.582896 | T37: 10.6291 | U37: 190.11503 | V37: 155.23983 | W37: 73.478439 | X37: 72.434902 | Y37: 64.507477 | Z37: 0.64852994 | AA37: 0.96240526 | AB37: 74.39917 | AC37: 70.470634 | AD37: 295.44165 | AE37: 299.05036 | AF37: 43.3638 | AG37: -0.52506801 | AH37: 0.5685664 | AI37: 305.85854 | AJ37: 292.24218 | AK37: 48.807045 | AL37: 50.823205 | AM37: 35.107038 | AN37: -1.0724705 | AO37: -0.73531374 | AP37: 53.9297 | AQ37: 47.71671
A38: 2020-02-04 | B38: 282.50211 | C38: 277.18916 | D38: 55.820395 | E38: -2.7916593 | F38: -2.7084002 | G38: 290.44612 | H38: 263.93221 | I38: 9180.9629 | J38: 8942.9603 | K38: 54.967283 | L38: 365.49773 | M38: 365.3421 | N38: 9685.9455 | O38: 8199.975 | P38: 189.2506 | Q38: 173.82842 | R38: 67.562838 | S38: 11.620441 | T38: 10.827368 | U38: 192.47158 | V38: 155.18526 | W38: 71.635292 | X38: 72.450291 | Y38: 50.568114 | Z38: 0.57148383 | AA38: 0.88422097 | AB38: 74.382593 | AC38: 70.517988 | AD38: 299.94452 | AE38: 299.09001 | AF38: 56.101579 | AG38: -0.21472632 | AH38: 0.41190786 | AI38: 305.9099 | AJ38: 292.27012 | AK38: 51.257626 | AL38: 50.784441 | AM38: 52.201454 | AN38: -0.86972557 | AO38: -0.7621961 | AP38: 53.846407 | AQ38: 47.722475
A39: 2020-02-05 | B39: 289.19571 | C39: 277.43652 | D39: 61.591354 | E39: -1.4019 | F39: -2.4471002 | G39: 291.41314 | H39: 263.45989 | I39: 9613.4238 | J39: 8987.4421 | K39: 62.996618 | L39: 377.51749 | M39: 367.77718 | N39: 9780.0447 | O39: 8194.8395 | P39: 204.23024 | Q39: 175.82038 | R39: 75.274834 | S39: 12.712387 | T39: 11.204372 | U39: 198.33023 | V39: 153.31054 | W39: 71.667015 | X39: 72.440106 | Y39: 50.765313 | Z39: 0.50713804 | AA39: 0.80880439 | AB39: 74.38736 | AC39: 70.492852 | AD39: 303.40836 | AE39: 299.17843 | AF39: 62.996043 | AG39: 0.30718336 | AH39: 0.39096296 | AI39: 306.18092 | AJ39: 292.17594 | AK39: 51.614079 | AL39: 50.747459 | AM39: 54.095665 | AN39: -0.67253346 | AO39: -0.74426358 | AP39: 53.746847 | AQ39: 47.74807
A40: 2020-02-06 | B40: 292.24512 | C40: 277.88543 | D40: 63.904582 | E40: -0.053823591 | F40: -1.9684449 | G40: 293.16642 | H40: 262.60444 | I40: 9729.8018 | J40: 9027.4803 | K40: 64.814731 | L40: 391.91619 | M40: 372.60498 | N40: 9885.8344 | O40: 8169.1263 | P40: 212.33908 | Q40: 177.89834 | R40: 78.284606 | S40: 14.069889 | T40: 11.777475 | U40: 205.53753 | V40: 150.25914 | W40: 73.149864 | X40: 72.43131 | Y40: 58.999051 | Z40: 0.56923528 | AA40: 0.76089057 | AB40: 74.363247 | AC40: 70.499372 | AD40: 304.4292 | AE40: 299.27095 | AF40: 64.752997 | AG40: 0.79402109 | AH40: 0.47157459 | AI40: 306.50759 | AJ40: 292.03431 | AK40: 51.703201 | AL40: 50.722507 | AM40: 54.580316 | AN40: -0.5032645 | AO40: -0.69606376 | AP40: 53.678936 | AQ40: 47.766079
A41: 2020-02-07 | B41: 287.92117 | C41: 278.11815 | D41: 58.522372 | E41: 0.65804502 | F41: -1.4431469 | G41: 293.87846 | H41: 262.35784 | I41: 9795.9434 | J41: 9070.1371 | K41: 65.841945 | L41: 404.0072 | M41: 378.88542 | N41: 9993.1344 | O41: 8147.1397 | P41: 222.72606 | Q41: 180.26636 | R41: 81.406823 | S41: 15.80171 | T41: 12.582322 | U41: 214.3548 | V41: 146.17792 | W41: 73.305473 | X41: 72.430294 | Y41: 59.759572 | Z41: 0.62381322 | AA41: 0.7334751 | AB41: 74.360271 | AC41: 70.500316 | AD41: 302.8067 | AE41: 299.28234 | AF41: 59.886146 | AG41: 1.036968 | AH41: 0.58465327 | AI41: 306.5416 | AJ41: 292.02309 | AK41: 50.081333 | AL41: 50.616463 | AM41: 45.223093 | AN41: -0.49429096 | AO41: -0.6557092 | AP41: 53.50068 | AQ41: 47.732246
A42: 2020-02-08 | B42: 287.92117 | C42: 278.35087 | D42: 58.522372 | E42: 1.2082777 | F42: -0.91286196 | G42: 294.56229 | H42: 262.13945 | I42: 9865.1191 | J42: 9128.0808 | K42: 66.929389 | L42: 414.39444 | M42: 385.98723 | N42: 10099.143 | O42: 8157.0185 | P42: 223.14651 | Q42: 183.07519 | R42: 81.522634 | S42: 17.012013 | T42: 13.46826 | U42: 221.52878 | V42: 144.6216 | W42: 73.305473 | X42: 72.429278 | Y42: 59.759572 | Z42: 0.65946472 | AA42: 0.71867302 | AB42: 74.357291 | AC42: 70.501264 | AD42: 302.8067 | AE42: 299.29374 | AF42: 59.886146 | AG42: 1.2154937 | AH42: 0.71082135 | AI42: 306.57546 | AJ42: 292.01201 | AK42: 50.081333 | AL42: 50.510418 | AM42: 45.223093 | AN42: -0.48162747 | AO42: -0.62089285 | AP42: 53.303668 | AQ42: 47.717168
A43: 2020-02-09 | B43: 287.92117 | C43: 278.58359 | D43: 58.522372 | E43: 1.6256022 | F43: -0.40516912 | G43: 295.2202 | H43: 261.94699 | I43: 10116.674 | J43: 9201.0323 | K43: 70.595385 | L43: 437.87718 | M43: 396.36522 | N43: 10240.125 | O43: 8161.9401 | P43: 228.57857 | Q43: 186.14809 | R43: 82.996207 | S43: 18.199714 | T43: 14.414551 | U43: 228.82405 | V43: 143.47214 | W43: 73.305473 | X43: 72.428262 | Y43: 59.759572 | Z43: 0.67988155 | AA43: 0.71091473 | AB43: 74.354307 | AC43: 70.502217 | AD43: 302.8067 | AE43: 299.30513 | AF43: 59.886146 | AG43: 1.3415125 | AH43: 0.83695958 | AI43: 306.60918 | AJ43: 292.00108 | AK43: 50.081333 | AL43: 50.404374 | AM43: 45.223093 | AN43: -0.46621729 | AO43: -0.58995774 | AP43: 53.085994 | AQ43: 47.722753
A44: 2020-02-10 | B44: 292.36792 | C44: 279.11606 | D44: 62.571382 | E44: 2.2887667 | F44: 0.13361804 | G44: 296.82243 | H44: 261.40969 | I44: 9856.6113 | J44: 9256.5682 | K44: 62.8398 | L44: 430.53957 | M44: 403.20009 | N44: 10311.839 | O44: 8201.2973 | P44: 223.52271 | Q44: 188.83937 | R44: 76.852826 | S44: 18.519527 | T44: 15.235546 | U44: 233.87092 | V44: 143.80782 | W44: 74.769989 | X44: 72.493705 | Y44: 66.962888 | Z44: 0.80495716 | AA44: 0.72972321 | AB44: 74.643469 | AC44: 70.343941 | AD44: 305.0672 | AE44: 299.45918 | AF44: 64.525699 | AG44: 1.6052819 | AH44: 0.99062405 | AI44: 307.12244 | AJ44: 291.79592 | AK44: 50.812073 | AL44: 50.350015 | AM44: 50.042694 | AN44: -0.39053816 | AO44: -0.55007382 | AP44: 52.946779 | AQ44: 47.75325
...

Sheet Vizualizacija
B2: CENTRALNI VIZUALNI DASHBOARD
B3: Svi tehnički i statistički grafikoni generirani kroz Python pipeline
B4: Grafikon: BOLLINGEROVE TRAKE | L4: Grafikon: EMA
B24: Grafikon: HISTOGRAM DNEVNIH PRINOSA | L24: Grafikon: KORELACIJSKA MATRICA CIJENE
B44: Grafikon: KUMULATIVNI PRIKAZ | L44: Grafikon: MACD
B64: Grafikon: ROLLING VOLATILNOST | L64: Grafikon: RSI
B84: Grafikon: SEZONALNOST | L84: Grafikon: SMA
